Workbook
Name Base_Type: Dropdownregeln!$E$2:$E$47
Name Beschreibung: Dropdownregeln!$F$2:$F$47
Name Category: Dropdownregeln!$D$2:$D$47
Name DataType: Dropdownregeln!$B$2:$B$47
Name DataTypes: #REF!
Name DataTypes: [1]Dropdownregeln!#REF!
Name FAIR_Prinzipien: Dropdownregeln!$I$2:$I$47
Name GLO_Object_Umsetzung: Anleitung!$F$167
Name GLO_Object_Zuordnung: Anleitung!$F$168
Name GLO_Object1: Anleitung!#REF!
Name GLO_Object10: Anleitung!$F$177
Name GLO_Object11: Anleitung!$F$178
Name GLO_Object12: Anleitung!$F$179
Name GLO_Object13: Anleitung!$F$180
Name GLO_Object14: Anleitung!$F$181
Name GLO_Object15: Anleitung!$F$182
Name GLO_Object16: Anleitung!$F$183
Name GLO_Object17: Anleitung!$F$184
Name GLO_Object18: Anleitung!$F$185
Name GLO_Object19: Anleitung!$F$186
Name GLO_Object2: Anleitung!$F$170
Name GLO_Object20: Anleitung!$F$187
Name GLO_Object21: Anleitung!$F$188
Name GLO_Object22: Anleitung!$F$189
Name GLO_Object3: Anleitung!#REF!
Name GLO_Object4: Anleitung!#REF!
Name GLO_Object5: Anleitung!#REF!
Name GLO_Object6: Anleitung!$F$173
Name GLO_Object7: Anleitung!$F$174
Name GLO_Object8: Anleitung!$F$175
Name GLO_Object9: Anleitung!$F$176
Name GLO_Property_Umsetzung: Anleitung!$K$167
Name GLO_Property_Zuordnung: Anleitung!$K$168
Name GLO_Property1: Anleitung!#REF!
Name GLO_Property10: Anleitung!$K$177
Name GLO_Property11: Anleitung!$K$178
Name GLO_Property12: Anleitung!$K$179
Name GLO_Property13: Anleitung!$K$180
Name GLO_Property14: Anleitung!$K$181
Name GLO_Property15: Anleitung!$K$182
Name GLO_Property16: Anleitung!$K$183
Name GLO_Property17: Anleitung!$K$184
Name GLO_Property18: Anleitung!$K$185
Name GLO_Property19: Anleitung!$K$186
Name GLO_Property2: Anleitung!$K$170
Name GLO_Property20: Anleitung!$K$187
Name GLO_Property3: Anleitung!$C$171
Name GLO_Property4: Anleitung!#REF!
Name GLO_Property5: Anleitung!$C$172
Name GLO_Property6: Anleitung!$K$173
Name GLO_Property7: Anleitung!$K$174
Name GLO_Property8: Anleitung!$K$175
Name GLO_Property9: Anleitung!$K$176
Name IFC_Data_Type: Dropdownregeln!$C$2:$C$47
Name ISG___Informationssicherheitsgesetz: Dropdownregeln!$H$2:$H$47
Name Merkmalskatalog_Start: '[2]MG Katalog'!#REF!
Name Objekt_Einordnung: Dropdownregeln!$A$2:$A$47
Name Objektkatalog_Start: [3]Wertekatalog!#REF!
Name Status: Dropdownregeln!$G$2:$G$47
Name Units: [1]Dropdownregeln!#REF!

Sheet Impressum
B1: Strukturvorlage Handlungsempfehlung Data Dictionaries
B3: Dokumenteninformationen
C4: Status | D4: Entwurf
C5: Version | D5: v20260510
C6: Letzte Änderung | D6: 46152
C7: Autor | D7: Bauen digital Schweiz / buildingSMART Switzerland (BdCH/bSCH)
B9: Trägerschaft
B12: Mit freundlicher Unterstützung von
C13: Armasuisse | E13: Schweizerische Bundesbahnen (SBB AG)
C14: B+S AG | E14: Schweizerischer Baumeisterverband (SBV)
C15: Basler & Hofmann AG | D15: Lignum Holzwirtschaft Schweiz | E15: Schweizerischer Ingenieur- und Architektenverein (SIA)
C16: Baumschlager Eberle Zürich AG | D16: Lombardi AG | E16: Stadt Luzern
C17: Buildup AG | D17: Losinger Marazzi AG | E17: Stadt Zürich
C18: Bundesamt für Strassen (ASTRA) | D18: Marti Tunnel AG | E18: Steinmann Ingenieure und Planer AG
C19: CRB | D19: MEGA | E19: Suissetec
C20: Fachgruppe für Untertagbau (FGU) | D20: Mensch und Maschine Schweiz AG | E20: Swissgee
C21: FHNW | D21: Open BIM Verband | E21: SWKI / die Planer
C22: Frutiger AG | D22: Penzel Valier AG | E22: Terradata AG
C23: HKG | D23: Rhomberg Sersa Rail Group Schweiz | E23: Walo AG
C24: IBG Engineering AG | D24: Roundtable Gebäudetechnik
C25: ILF BERATENDE INGENIEURE AG | D25: Schindler Aufzüge AG
C26: Implenia Schweiz AG | D26: Siemens AG
B28: Abgrenzung | D28: Fokus auf Austauschformat IFC 4.3.2.0 (IFC4X3_ADD2)
D29: Andere Formate (z. B. CityGML, gbXML, LandXML) sind kein Bestandteil
D30: Keine Abbildung von Geodaten (Geologie, Topographie, Bewuchs, Gewässer)
D31: Strukturvorlage ist eine methodische Grundlage, kein vollständiger Datenkatalog
D32: Vollständige Datenkataloge müssen in Datenbanken realsiert werden
D33: Die Handlungsempfehlung ist keine Implementierungsrichtlinie für Softwareentwicklung
D34: Die Strukturvorlage ist ein Best Practice Beispiel und kann jederzeit an neue Anforderungen angepasst werden. Es wird davon abgeraten, auf der Basis der Strukturvorlage Applikationen oder Tools zu entwickeln.
D35: Keine konkrete Implementierung oder Vernetzung von Datenkatalogen
B38: Copyright
D41: https://creativecommons.org/licenses/by-nc-sa/4.0/
D49: mailto:info@bauen-digital.ch

Sheet Anleitung
A1: Anleitung Strukturvorlage Data Dictionaries
B3: Inhaltsverzeichnis
B5: 1 | C5: Handhabung
B6: 2 | C6: Governance
B7: 3 | C7: Objekte
B8: 4 | C8: Klassifikationen
B9: 5 | C9: Merkmale
B10: 6 | C10: Werteliste
B11: 7 | C11: Dokumente
B13: Hinweise zur Handhabung
D15: B | E15: C | F15: D | G15: E
B16: Hinweise zur Handhabung | C16: Erforderlich | D16: Erforderlich für Data Dictionary | E16: Sprachen | F16: Referenziert / System generiert | G16: Dropdown Liste
B17: A | C17: Erforderlich für Objektkatalog
C18: Definiert die Mindestandorderugen an einen Katalog. Unterscheidung zwischen ja = erforderlich / empfohlen / <leer> = nicht notwendig
B19: B | C19: Erforderlich für Data Dictionary
C20: Definiert die Mindestandorderugen an ein in einer Datenbank eingepfegtes Data Dictionaries. Unterscheidung zwischen ja = erforderlich / empfohlen / <leer> = nicht notwendig
B21: C | C21: Sprachen
C22: Angabe zur Sprache: mehrsprachig = muss in der für den Katalog führenden Sprache enthalten sein / EN, DE, FR, IT = gibt Sprache zwingend vor / Sprachneutral = nicht von Sprache abängig
B23: D | C23: Referenziert / System generiert
C24: Darf nicht vom Erstelle manuell ausgefüllt werden, sonern wird auf eine Quelle referenziert, resp. von eine Datenbank automatisch generiert
B25: E | C25: Dropdown Liste
C26: Verweist auf die Dropdownliste in diesem Template
A28: 2 | B28: Governance
B30: Vorgabe einer minimalen Governance für die verschiedenen Kataloge
B31: Optional können aller Regeln der SN EN ISO 23386 ergänzt werden
B33: A | C33: B | D33: C | E33: D | F33: E | G33: F | H33: G
B34: Governance | C34: Status | D34: Versionsdatum | E34: Herkunft (PROV) | F34: Regeln zur Festlegung von Merkmalen | G34: Regeln zur Festlegung von Merkmalsgruppen | H34: Management-Regeln für die Erstellung und Pflege
B35: B | C35: Vorgeschriebner Status des Merkmals während seines Lebenszyklus (Enumeration: active / inactive)
B36: C | C36: Datum der Version. Format nach ISO 8601 = YYYY-MM-DDThh:mm:ssTDZ (T = festes Trennzeichen zwischen Datum und Uhrzeit / TDZ = Zeitzonenbezeichnung. Z = UTC, Abweichung zu UTC angeben)
C38: EN: PROV = Provenance, DE = Herkunft, Entstehungsgeschichte oder Nachweis der Datenherkunft
C39: Um eindeutig, maschinenlesbar und für den Menschen verständlich zu sein, müssen Merkmale als Liste von Attributen festgelegt werden. Einige Attribute sind zwingend erforderlich und andere sind freigestellt.
C42: Um eindeutig, maschinenlesbar und für den Menschen verständlich zu sein, müssen Merkmalsgruppen als Liste von Attributen festgelegt werden. Einige Attribute sind zwingend erforderlich und andere sind freigestellt.
C45: Verbindliche Regeln zur Erstellung, Pflege und Versionierung von Merkmalen und Merkmaslgruppen sowie zur koordinierten Abstimmung und Freigabe zwischen Akteuren zur Sicherstellung von Qualität, Konsistenz und Interoperabilität.
B50: Objekte
C52: B | E52: D | F52: E | G52: F | H52: G | I52: H | J52: I | K52: J | L52: K | M52: L | N52: M | O52: N | P52: O | R52: Q | S52: R
B53: Strukturelle Einordnung | C53: Domäne | E53: Kategorie | F53: Objekte | G53: GUID/URI | H53: Objekt-ID | I53: Objekt-Einordnung | J53: Bezeichnung | K53: Designation | L53: Beschreibung | M53: Description | N53: IFC 4.3.2.0 (IFC4X3_ADD2) | O53: GUID/URI | P53: IfcObject Entity | R53: PredefinedType | S53: ObjectType
B55: Strukturelle Einordnung
C57: B | E57: D
B58: Strukturelle Einordnung | C58: Domäne | E58: Kategorie
C59: Fachlicher Gesamtbereich, oberste Gliederung nach Disziplin Biespiele: Architektur, Tragwerk, HVAC, Verkehrswegebau, Bahntechnik, Werkleitungen
...

Sheet Dictionary_core
A1: HE-SEM Data Dictionary — Core Metadata (mandatory authoring block)
A2: Field | B2: Value | C2: Requirement | D2: Notes / Maps to
A3: ── IDENTIFICATION ──
A4: OrganizationCode | B4: bDCH | C4: REQUIRED | D4: Short org code — appears in all IRIs
A5: DictionaryCode | C5: REQUIRED | D5: Short dictionary code e.g. hesem-core
A6: DictionaryName (DE) | B6: Data Dictionary Flächenmanagement | C6: REQUIRED | D6: Core authoring title in German — minimal DCAT/i14y anchor
A7: DictionaryName (FR) | C7: OPTIONAL | D7: Optional multilingual title support
A8: DictionaryName (EN) | B8: Data Dictionary Area Management | C8: OPTIONAL | D8: Optional multilingual title support
A9: DictionaryVersion | B9: 0.0.1 | C9: REQUIRED | D9: Semantic versioning: MAJOR.MINOR.PATCH
A10: DictionaryUri | C10: REQUIRED | D10: Base IRI — UseOwnUri always true
C11: Guide | D11: Private organisations may keep only this tab and delete Dictionary_public.
A12: ── GOVERNANCE ──
A13: LifecycleStatus | B13: Candidate | C13: REQUIRED | D13: Governance state used to derive i14y registration status
A15: LEGEND:
A16: REQUIRED | B16: Must be filled before validation/export
A17: OPTIONAL | B17: Fill if available

Sheet Dictionary_public
A1: HE-SEM Data Dictionary — Public Metadata (optional extended publication block)
A2: Field | B2: Value | C2: Requirement | D2: Notes / Maps to
A3: ── GOVERNANCE / PUBLISHING ──
A4: Owner / Publisher | C4: REQUIRED WHEN USED | D4: dct:publisher / i14y publisher mapping
A5: ContactEmail | C5: REQUIRED WHEN USED | D5: dcat:contactPoint / i14y contact
A6: Description (DE) | C6: REQUIRED WHEN USED | D6: dct:description@de
A7: Description (FR) | C7: OPTIONAL | D7: dct:description@fr
A8: Description (EN) | C8: OPTIONAL | D8: dct:description@en
A9: PrimaryLanguage | C9: REQUIRED WHEN USED | D9: Primary metadata/content language
A10: MetadataLanguages | C10: OPTIONAL | D10: Additional metadata languages; delimited list allowed
A11: ReleaseDate | C11: OPTIONAL | D11: dct:issued — format YYYY-MM-DD
A12: ModifiedDate | C12: OPTIONAL
A13: QualityAssuranceProcedure | C13: OPTIONAL
A14: QualityAssuranceProcedureUrl | C14: OPTIONAL
A15: ── DISCOVERY / CATALOG METADATA ──
A16: Keywords (DE) | C16: OPTIONAL | D16: German keywords/tags — dcat:keyword@de
A17: Keywords (FR) | C17: OPTIONAL | D17: French keywords/tags — dcat:keyword@fr
A18: Keywords (EN) | C18: OPTIONAL | D18: English keywords/tags — dcat:keyword@en
A19: AccessRights | C19: OPTIONAL | D19: Access rights / visibility statement — dct:accessRights
A20: eCH_Theme | C20: OPTIONAL | D20: Swiss eCH thematic classification / topic category
A21: SpatialCoverage | C21: OPTIONAL | D21: Geographic scope or covered territory — dct:spatial
A22: TemporalCoverage | C22: OPTIONAL | D22: Covered time period / validity period — dct:temporal
A23: DocumentationURLs | C23: OPTIONAL | D23: Supporting documentation links; delimited list allowed
A24: RelatedResourceURLs | C24: OPTIONAL | D24: Related datasets/resources links — dct:relation
A25: ApplicableLegislation | C25: OPTIONAL | D25: Applicable legal basis / legislation references
A26: ── LICENSING ──
A27: License | C27: OPTIONAL | D27: Human-readable license name — dct:license
A28: LicenseUrl | C28: OPTIONAL | D28: Resolvable license URI/URL — dct:license
A29: ── TECHNICAL ENDPOINTS ──
A30: SPARQL_Endpoint | C30: OPTIONAL | D30: SPARQL endpoint URL for published graph access
A31: TTL_Download_URL | C31: OPTIONAL | D31: Download URL for Turtle/RDF serialization — dcat:distribution
A32: JSON_Download_URL | C32: OPTIONAL | D32: Download URL for JSON/JSON-LD serialization — dcat:distribution
A33: MoreInfoUrl | C33: OPTIONAL | D33: Landing page / homepage
A34: ── STANDARDS ALIGNMENT ──
A35: ConformsTo_ISO23386 | C35: OPTIONAL | D35: dct:conformsTo — property methodology
A36: ConformsTo_ISO12006_3 | C36: OPTIONAL
A37: ConformsTo_DCAT_AP_CH | C37: OPTIONAL
A38: VersionNotes (DE) | C38: OPTIONAL
A39: VersionNotes (FR) | C39: OPTIONAL
A40: VersionNotes (EN) | C40: OPTIONAL
...

Sheet Objekte
A1: Filter | B1: Hinweise zur Handhabung | C1: Strukturelle Einordnung | D1: Domäne | E1: System | F1: Kategorie | G1: Objekte | H1: GUID/URI | I1: Objekt-ID | J1: Objekt-Code | K1: Objekt-Einordnung | L1: Bezeichnung (DE) | M1: Designation (EN) | N1: Désignation (FR) | O1: Designazione (IT) | P1: Beschreibung (DE) | Q1: Description (EN) | R1: Description (FR) | S1: Descrizione (IT) | T1: IFC 4.3.2.0 (IFC4X3_ADD2) | U1: Objekte.IFC_URI | V1: IfcObject Entity | W1: IfcTypeObject Entity | X1: PredefinedType | Y1: ObjectType | Z1: Governance | AA1: Status | AB1: Versionsdatum | AC1: Herkunft (PROV) | AD1: Klassifikationen | AE1: Objekte.RelatedDocument (Document-ID)
B2: Erforderlich für Merkmalkatalog
B3: Erforderlich für Data Dictionary
B4: Sprachen | D4: multilingual | E4: multilingual | F4: multilingual | H4: multilingual | I4: multilingual | J4: multilingual | K4: multilingual | L4: DE | M4: EN | N4: FR | O4: IT | P4: DE | Q4: EN | R4: FR | S4: IT | U4: multilingual | V4: multilingual | W4: multilingual | X4: multilingual | Y4: multilingual | AA4: multilingual | AB4: multilingual | AC4: multilingual | AE4: multilingual
B5: Referenziert / System generiert | H5: referenced | I5: system-generated | U5: referenced | V5: referenced | W5: referenced | X5: referenced | Y5: referenced | AA5: referenced | AB5: referenced | AC5: referenced | AE5: referenced
B6: Dropdown Liste | K6: Objekt-Einordnung | AA6: Status
B7: Validierung | D7: user defined | E7: user defined | F7: user defined | H7: not validated. Info: If available system-generated URI / user defined backend reference | I7: system-generated from Designation (EN) | J7: user defined | K7: must match Dropdownregeln.Objekt-Einordnung | L7: user defined | M7: user defined | N7: user defined | O7: user defined | P7: user defined | Q7: user defined | R7: user defined | S7: user defined | U7: validated against identifiers from https://search.bsdd.buildingsmart.org/uri/buildingsmart/ifc/4.3 | V7: validated against IFC 4.3 entity identifiers | W7: validated against IFC 4.3 entity identifiers | X7: validated against IFC predefined types when applicable | Y7: validated against IFC 4.3 entity identifiers | AA7: must match Dropdownregeln.Status | AB7: date format YYYY-MM-DD | AC7: user defined | AE7: must reference Dokumente.Document-ID or empty = Organisation
J8: BdCH_O_31010000 | K8: Räumliche Struktur | L8: Geschossebene | M8: Elevation | U8: https://identifier.buildingsmart.org/uri/buildingsmart/ifc/4.3/class/IfcBuildingStorey | V8: IfcBuildingStorey | AA8: active | AB8: 2026-06-18T15:30+02:00 | AC8: BdCH | AE8: =Dokumente!$H$8 -> Dokumenttypenkatalog
J9: BdCH_O_31010001 | K9: Räumliche Struktur | L9: Grundstückfläche | M9: Site area | P9: Parzellenfläche (Grundstückfläche gemäss SIA 416) | Q9: Site area (plot area according to SIA 416) | U9: https://identifier.buildingsmart.org/uri/buildingsmart/ifc/4.3/class/IfcSite | V9: IfcSite | W9: IfcSite | AA9: active | AB9: 2026-06-18T15:30+02:00 | AC9: BdCH | AE9: =Dokumente!$H$8 -> Dokumenttypenkatalog
J10: BdCH_O_31010002 | K10: Räumliche Struktur | L10: Umgebungsfläche | M10: Surrounding area | P10: Umgebungsfläche gemäss SIA 416 | Q10: Surrounding area according to SIA 416 | U10: https://identifier.buildingsmart.org/uri/buildingsmart/ifc/4.3/class/IfcSpace | V10: IfcSpace | W10: IfcSpace | X10: USERDEFINED | Y10: SITE_AREA | AA10: active | AB10: 2026-06-18T15:30+02:00 | AC10: BdCH | AE10: =Dokumente!$H$8 -> Dokumenttypenkatalog
J11: BdCH_O_31010003 | K11: Räumliche Struktur | L11: Geschossvolumen | M11: Gross floor area | P11: Volumetrische Darstellung der Geschossflächen (brutto) und Geschossvolumen gemäss SIA 416 | Q11: Volumetric representation of gross floor areas and storey volumes according to SIA 416 | U11: https://identifier.buildingsmart.org/uri/buildingsmart/ifc/4.3/class/IfcSpace | V11: IfcSpace | W11: IfcSpace | X11: USERDEFINED | Y11: SURROUNDING_AREA | AA11: active | AB11: 2026-06-18T15:30+02:00 | AC11: BdCH | AE11: =Dokumente!$H$8 -> Dokumenttypenkatalog
J12: BdCH_O_31010004 | K12: Räumliche Struktur | L12: Nettogeschossfläche | M12: Room | P12: Innenräume (Nettogeschossflächen gemäss SIA 416) | Q12: Internal spaces (net floor areas according to SIA 416) | U12: https://identifier.buildingsmart.org/uri/buildingsmart/ifc/4.3/class/IfcSpace | V12: IfcSpace | W12: IfcSpace | X12: GFA | AA12: active | AB12: 2026-06-18T15:30+02:00 | AC12: BdCH | AE12: =Dokumente!$H$8 -> Dokumenttypenkatalog
J13: BdCH_O_31010005 | K13: Räumliche Struktur | L13: Aussen-Nettogeschossfläche | M13: External room | P13: Aussenräume (Aussen-Nettogeschossflächen gemäss SIA 416) | Q13: External spaces (external net floor areas according to SIA 416) | U13: https://identifier.buildingsmart.org/uri/buildingsmart/ifc/4.3/class/IfcSpace | V13: IfcSpace | W13: IfcSpace | X13: USERDEFINED | Y13: ROOM | AA13: active | AB13: 2026-06-18T15:30+02:00 | AC13: BdCH | AE13: =Dokumente!$H$8 -> Dokumenttypenkatalog
J14: BdCH_O_31010006 | K14: Räumliche Struktur | L14: Stellplatz | M14: Parking space | P14: Stellplätze wie z.B. Autoparkplatz, Mofa-Parkplatz, Velostellplatz, Feuerwehrstellplatz | Q14: Parking spaces such as car parking spaces, moped parking, bicycle parking, fire service access/parking bays | U14: https://identifier.buildingsmart.org/uri/buildingsmart/ifc/4.3/class/IfcSpace | V14: IfcSpace | W14: IfcSpace | X14: USERDEFINED | Y14: EXTERNAL_ROOM | AA14: active | AB14: 2026-06-18T15:30+02:00 | AC14: BdCH | AE14: =Dokumente!$H$8 -> Dokumenttypenkatalog
J15: BdCH_O_31010007 | K15: Räumliche Struktur | L15: Vermietbare Fläche | M15: Rentable area | P15: Darstellung der vermietbaren Fläche, insofern diese von den Nettoraumflächen differiert | Q15: Representation of lettable area where this differs from net floor areas | U15: https://identifier.buildingsmart.org/uri/buildingsmart/ifc/4.3/class/IfcSpace | V15: IfcSpace | W15: IfcSpace | X15: PARKING | AA15: active | AB15: 2026-06-18T15:30+02:00 | AC15: BdCH | AE15: =Dokumente!$H$8 -> Dokumenttypenkatalog
U16: https://identifier.buildingsmart.org/uri/buildingsmart/ifc/4.3/class/IfcSpace | V16: IfcSpace | W16: IfcSpace | X16: USERDEFINED | Y16: RENTABLE_AREA | AA16: active | AB16: 2026-06-18T15:30+02:00 | AC16: BdCH | AE16: =Dokumente!$H$8 -> Dokumenttypenkatalog

Sheet Merkmale
A1: Filter | B1: Hinweise zur Handhabung | C1: Merkmale | D1: GUID/URI | E1: Merkmal-ID | F1: Merkmal-Code | G1: Bezeichnung (DE) | H1: Designation (EN) | I1: Désignation (FR) | J1: Designazione (IT) | K1: Beschreibung (DE) | L1: Description (EN) | M1: Description (FR) | N1: Descrizione (IT) | O1: DataType (Base Type) | P1: DataType (IFC) | Q1: Werteliste-ID | R1: IFC 4.3.2.0 (IFC4X3_ADD2) | S1: IFC_URI | T1: IfcPropertySet (Pset) IfcQuantitySet (Qto) | U1: Einheit-Code | V1: QUDT URI | W1: Unit Name (EN) | X1: Einheit-Name (DE) | Y1: Nom de l’unité (FR) | Z1: Nome unità (IT) | AA1: Governance (Merkmale) | AB1: Status | AC1: Versionsdatum | AD1: Herkunft (PROV)
B2: Erforderlich für Merkmalkatalog
B3: Erforderlich für Data Dictionary
B4: Sprachen | D4: multilingual | E4: multilingual | F4: multilingual | G4: DE | H4: EN | I4: FR | J4: IT | K4: DE | L4: EN | M4: FR | N4: IT | O4: multilingual | P4: multilingual | Q4: multilingual | S4: multilingual | T4: multilingual | U4: multilingual | V4: multilingual | W4: EN | X4: DE | Y4: FR | Z4: IT | AB4: multilingual | AC4: multilingual | AD4: multilingual
B5: Referenziert / System generiert | D5: referenced | E5: system-generated | O5: referenced | P5: referenced | Q5: referenced | S5: referenced | T5: referenced | V5: referenced | W5: system-generated | X5: system-generated | Y5: system-generated | Z5: system-generated | AB5: referenced | AC5: referenced | AD5: referenced
B6: Dropdown Liste | O6: DataType | P6: IFC Data Type | AB6: Status
B7: Validierung | D7: not validated. Info: If available system-generated URI / user defined backend reference | E7: system-generated from Designation (EN) | F7: user defined | G7: user defined | H7: user defined | I7: user defined | J7: user defined | K7: user defined | L7: user defined | M7: user defined | N7: user defined | O7: must match Dropdownregeln.DataType | P7: must match Dropdownregeln.IFC Data Type | Q7: must reference Werte.Werteliste-ID if used | S7: validated against identifiers from https://search.bsdd.buildingsmart.org/uri/buildingsmart/ifc/4.3 | T7: validated against IFC 4.3 property/quantity set identifiers when IFC_URI is present | U7: user defined | V7: validated against QUDT unit ontology from https://qudt.org/tools/qudt-reference-explorer/ | W7: system-generated from QUDT URI | X7: system-generated from QUDT URI | Y7: system-generated from QUDT URI | Z7: system-generated from QUDT URI | AB7: must match Dropdownregeln.Status | AC7: date format YYYY-MM-DD | AD7: user defined
F8: BdCH_P_31020000 | G8: Vordefinierter Typ | H8: PredefinedType | K8: Vordefinierter Typ (Selbsterklärend) | L8: PredefinedType (self-explanatory) | O8: STRING | P8: IfcLabel | T8: (IfcSpace attribute) | AB8: Preview | AD8: BdCH
F9: BdCH_P_31020001 | G9: Objekttyp | H9: ObjectType | K9: Objekttyp (Selbsterklärend) | L9: ObjectType (self-explanatory) | O9: STRING | P9: IfcLabel | T9: (IfcObject attribute)
F10: BdCH_P_31020002 | G10: ID | H10: Name | K10: Eindeutige Raumnummer bzw. Geschossnummer gemäss Nummerierungskonzept | L10: Unique room number or floor number according to numbering scheme | O10: STRING | P10: IfcLabel | T10: (IfcRoot attribute)
F11: BdCH_P_31020003 | G11: Raumbezeichnung | H11: LongName | K11: Bezeichnung | L11: Designation | O11: STRING | P11: IfcLabel | T11: (IfcSpatialElement attribute)
F12: BdCH_P_31020004 | G12: Flächenart SIA 416 | H12: SIA_416_2003_Code | K12: Klassifizierung gemäss SIA 416 / 2003 | L12: Classification according to SIA 416 / 2003 | O12: STRING | P12: IfcLabel
F13: BdCH_P_31020005 | G13: Flächenart SIA 416 | H13: SIA_416_2003_Label | K13: Klassifizierung gemäss SIA 416 / 2003 | L13: Classification according to SIA 416 / 2003 | O13: STRING | P13: IfcLabel
F14: BdCH_P_31020006 | G14: Raumbezeichnung SIA 380 | H14: SIA_380_2015_Code | K14: Klassifizierung gemäss SIA 380 / 2015 | L14: Classification according to SIA 380 / 2015 | O14: STRING | P14: IfcLabel
F15: BdCH_P_31020007 | G15: Raumbezeichnung SIA 380 | H15: SIA_380_2015_Label | K15: Klassifizierung gemäss SIA 380 / 2015 | L15: Classification according to SIA 380 / 2015 | O15: STRING | P15: IfcLabel
F16: BdCH_P_31020008 | G16: Raumnutzung SIA 2024 | H16: SIA_2024_2021_Code | K16: Klassifizierung gemäss SIA 2024 / 2021 | L16: Classification according to SIA 2024 / 2021 | O16: STRING | P16: IfcLabel
F17: BdCH_P_31020009 | G17: Raumnutzung SIA 2024 | H17: SIA_2024_2021_Label | K17: Klassifizierung gemäss SIA 2024 / 2021 | L17: Classification according to SIA 2024 / 2021 | O17: STRING | P17: IfcLabel
F18: BdCH_P_31020010 | G18: Flächenart d0165 | H18: SIA_d0615_2000_Code | K18: Klassifizierung gemäss SIA D 0165 / 2000 | L18: Classification according to SIA D 0165 / 2000 | O18: STRING | P18: IfcLabel
F19: BdCH_P_31020011 | G19: Flächenart d0165 | H19: SIA_d0615_2000_Label | K19: Klassifizierung gemäss SIA D 0165 / 2000 | L19: Classification according to SIA D 0165 / 2000 | O19: STRING | P19: IfcLabel
F20: BdCH_P_31020012 | G20: Raumnutzung | H20: ProgramUse | K20: Raumnutzung gemäss Raumprogramm | L20: Room usage according to room programme | O20: STRING | P20: IfcLabel
F21: BdCH_P_31020013 | G21: Raumtyp | H21: RoomType | K21: Raumtyp (Funktionstyp) gemäss Raumkatalog (Raumdatenblätter) | L21: Room type (functional type) according to room catalogue (room data sheets) | O21: STRING | P21: IfcLabel
F22: BdCH_P_31020014 | G22: Einheitstyp | H22: UnitType | K22: Einheitstyp, insb. Wohnungstyp z.B. 3,5-Zi | L22: Unit type, in particular dwelling type (e.g. 3.5-room flat) | O22: STRING | P22: IfcLabel
F23: BdCH_P_31020015 | G23: Einheitsnummer | H23: Unit_ID | K23: Eindeutige Einheitsnummer (ID) gemäss Nummerierungskonzept für Verkaufs- bzw. Mieteinheiten, z.B. Wohnungsnummer | L23: Unique unit number (ID) according to numbering scheme for sale or rental units (e.g. apartment number) | O23: STRING | P23: IfcLabel
... F36: BdCH_P_31020028 | G36: Vermietbarkeit | H36: IsRentable | K36: Vermietbarkeit | L36: Letting suitability | O36: BOOLEAN | P36: IfcBoolean
D37: https://identifier.buildingsmart.org/uri/buildingsmart/ifc/4.3/prop/IsExternal | F37: BdCH_P_31020029 | G37: Aussenraum | H37: IsExternal | K37: Angabe, ob das Element für die Verwendung im Aussenbereich vorgesehen ist (TRUE) oder nicht (FALSE). Bei (TRUE) handelt es sich um ein Aussenelement, das ein Gebäude nach außen abschliesst. | L37: Indicates whether the element is intended for outdoor use (TRUE) or not (FALSE). If set to (TRUE), the element is an external element that forms the outer boundary of a building. | O37: BOOLEAN | P37: IfcBoolean | T37: Pset_SpaceCommon
D38: https://identifier.buildingsmart.org/uri/buildingsmart/ifc/4.3/prop/OccupancyType | F38: BdCH_P_31020030 | G38: Nutzungsart | H38: OccupancyType | K38: Nutzungsart dieses Objekts; sie wird gemäss den geltenden nationalen Bauvorschriften definiert. | L38: Occupancy type for this object.; It is defined according to the presiding national building code. | O38: STRING | P38: IfcLabel | T38: Pset_SpaceOccupancyRequirements
F39: BdCH_P_31020031 | G39: Raumnutzhöhe | H39: MinimumHeadroom | K39: Lichte Höhe | L39: Effective clear height | O39: REAL | P39: IfcLengthMeasure | T39: Pset_SpaceOccupancyRequirements
D40: https://identifier.buildingsmart.org/uri/buildingsmart/ifc/4.3/prop/OccupancyNumberPeak | F40: BdCH_P_31020032 | G40: Personenbelegung geplant | H40: OccupancyNumberPeak | K40: Maximale Anzahl Personen für die zugewiesene Nutzung dieses Raums in Spitzenzeiten. | L40: Maximal number of people required for the activity assigned to this space in peak time. | O40: INTEGER | P40: IfcInteger | T40: Pset_SpaceOccupancyRequirements
D41: https://identifier.buildingsmart.org/uri/buildingsmart/ifc/4.3/prop/OccupancyNumber | F41: BdCH_P_31020033 | G41: Personenbelegung ist | H41: OccupancyNumber | K41: Anzahl Personen für die zugewiesene Nutzung dieses Raums. | L41: Number of people required for the activity assigned to this space. | O41: INTEGER | P41: IfcInteger | T41: Pset_SpaceOccupancyRequirements
D42: https://identifier.buildingsmart.org/uri/buildingsmart/ifc/4.3/prop/FloorCovering | F42: BdCH_P_31020034 | G42: Bodenbelag | H42: FloorCovering | K42: Kennzeichnung des Materials bzw. der Oberfläche des Bodenbelags im Raum. Die Kennzeichnung wird für Raumbuchinformationen verwendet und häufig im Raumstempel angezeigt. Die Materialinformation wird bereitgestellt, sofern kein Covering-Objekt (Typ=FLOORING) mit eigener Geometrie und Materialzuweisung vorhanden ist. Bei Inkonsistenzen hat die Materialzuweisung der Covering-Elemente Vorrang. | L42: Label to indicate the material or finish of the space flooring. The label is used for room book information and often displayed in room stamp.The material information is provided in absence of an Covering (type=FLOORING) object with own shape representation and material assignment. In case of inconsistency the material assigned to Covering elements takes precedence. | O42: STRING | P42: IfcLabel | T42: Pset_SpaceCoveringRequirements
D43: https://identifier.buildingsmart.org/uri/buildingsmart/ifc/4.3/prop/WallCovering | F43: BdCH_P_31020035 | G43: Wandbelag | H43: WallCovering | K43: Kennzeichnung des Materials bzw. der Oberfläche der Wandbekleidung im Raum. Die Kennzeichnung wird für Raumbuchinformationen verwendet und häufig im Raumstempel angezeigt. Die Materialinformation wird bereitgestellt, sofern kein Covering-Objekt (Typ=CLADDING) mit eigener Geometrie und Materialzuweisung vorhanden ist. Bei Inkonsistenzen hat die Materialzuweisung der Covering-Elemente Vorrang. | L43: Label to indicate the material or finish of the space cladding. The label is used for room book information and often displayed in room stamp.The material information is provided in absence of an Covering (type=CLADDING) object with own shape representation and material assignment. In case of inconsistency the material assigned to Covering elements takes precedence | O43: STRING | P43: IfcLabel | T43: Pset_SpaceCoveringRequirements
D44: https://identifier.buildingsmart.org/uri/buildingsmart/ifc/4.3/prop/CeilingCovering | F44: BdCH_P_31020036 | G44: Deckenmaterial | H44: CeilingCovering | K44: Kennzeichnung des Materials bzw. der Oberfläche der Raumdecke. Die Kennzeichnung wird für Raumbuchinformationen verwendet und häufig im Raumstempel angezeigt. Die Materialinformation wird bereitgestellt, sofern kein Covering-Objekt (Typ=CEILING) mit eigener Geometrie und Materialzuweisung vorhanden ist. Bei Inkonsistenzen hat die Materialzuweisung der Covering-Elemente Vorrang. | L44: Label to indicate the material or finish of the space ceiling. The label is used for room book information and often displayed in room stamp.The material information is provided in absence of an Covering (type=[[CEILING]]) object with own shape representation and material assignment. In case of inconsistency the material assigned to Covering elements takes precedence. | O44: STRING | P44: IfcLabel | T44: Pset_SpaceCoveringRequirements
D45: https://identifier.buildingsmart.org/uri/buildingsmart/ifc/4.3/prop/NaturalVentilation | F45: BdCH_P_31020037 | G45: Natürliche Belüftung | H45: NaturalVentilation | K45: Angabe, ob für den Raum natürliche Lüftung erforderlich ist (TRUE) oder nicht (FALSE). | L45: Indication whether the space is required to have natural ventilation (TRUE), or not (FALSE). | O45: BOOLEAN | P45: IfcBoolean
D46: https://identifier.buildingsmart.org/uri/buildingsmart/ifc/4.3/prop/NaturalVentilationRate | F46: BdCH_P_31020038 | G46: Natürliche Luftwechselrate | H46: NaturalVentilationRate | K46: Angabe der erforderlichen natürlichen Luftwechselrate (in Luftwechseln pro Stunde). | L46: Indication of the requirement of a particular natural air ventilation rate, given in air changes per hour. | O46: REAL | P46: IfcVolumetricFlowRateMeasure
D47: https://identifier.buildingsmart.org/uri/buildingsmart/ifc/4.3/prop/MechanicalVentilation | F47: BdCH_P_31020039 | G47: Mechanische Belüftung | H47: MechanicalVentilation | K47: Angabe, ob für den Raum mechanische Lüftung erforderlich ist (TRUE) oder nicht (FALSE). | L47: Indication whether the space is required to have mechanical ventilation (TRUE), or not (FALSE). | O47: BOOLEAN | P47: IfcBoolean
D48: https://identifier.buildingsmart.org/uri/buildingsmart/ifc/4.3/prop/MechanicalVentilationRate | F48: BdCH_P_31020040 | G48: Mechanische Luftwechselrate | H48: MechanicalVentilationRate | K48: Angabe der erforderlichen mechanischen Luftwechselrate (in Luftwechseln pro Stunde). | L48: Indication of the requirement of a particular mechanical air ventilation rate, given in air changes per hour. | O48: REAL | P48: IfcVolumetricFlowRateMeasure
D49: https://identifier.buildingsmart.org/uri/buildingsmart/ifc/4.3/prop/AirConditioning | F49: BdCH_P_31020041 | G49: Klimatisiert | H49: AirConditioning | K49: Angabe, ob für diesen Raum eine Klimatisierung erforderlich ist (TRUE) oder nicht (FALSE). | L49: Indication whether this space requires air conditioning provided (TRUE) or not (FALSE). | O49: BOOLEAN | P49: IfcBoolean
D50: https://identifier.buildingsmart.org/uri/buildingsmart/ifc/4.3/prop/TemperatureSetPoint | F50: BdCH_P_31020042 | G50: Temperatur Ziel | H50: TemperatureSetPoint | K50: Temperatur-Sollwertbereich und Standard-Sollwert. | L50: The temperature setpoint range and default setpoint. | O50: REAL | P50: IfcThermodynamicTemperatureMeasure
D51: https://identifier.buildingsmart.org/uri/buildingsmart/ifc/4.3/prop/HumiditySetPoint | F51: BdCH_P_31020043 | G51: Luftfeuchtigkeit Ziel | H51: HumiditySetPoint | K51: Geforderte Luftfeuchtigkeit des Raums bzw. der Zone aus Sicht Nutzer/Planer. Falls keine sommer- oder winterbezogenen Anforderungen angegeben sind, gilt der Wert ganzjährig, ansonsten für die Übergangszeit. Diese Eigenschaft ist anzugeben, sofern kein Feuchtebereich (Min–Max) verfügbar ist. | L51: Humidity of the space or zone that is required from user/designer view point. If no summer or winter space humidity requirements are given, it applies all year, otherwise for the intermediate period. Provide this property, if no humidity range (Min-Max) is available. | O51: REAL | P51: IfcReal
D52: https://identifier.buildingsmart.org/uri/buildingsmart/ifc/4.3/prop/FireExit | F52: BdCH_P_31020044 | G52: Fluchtweg | H52: FireExit | K52: Angabe, ob dieses Objekt im Brandfall als Ausgang dient (TRUE) oder nicht (FALSE). | L52: Indication whether this object is designed to serve as an exit in the case of fire (TRUE) or not (FALSE). | O52: BOOLEAN | P52: IfcBoolean | T52: Pset_SpaceFireSafetyRequirements
...

Sheet Werte
A1: Filter | B1: Hinweise zur Handhabung | C1: Wertekatalog | D1: GUID/URI | E1: Werteliste-ID | F1: Werteliste-Code | G1: Bezeichnung (DE) | H1: Désignation (FR) | I1: Designazione (IT) | J1: Designation (EN) | K1: EnumerationValues (EN) | L1: Werteliste (DE) | M1: Liste de valeurs (FR) | N1: Lista valori (IT) | O1: Einheiten | P1: Governance | Q1: Status | R1: Versionsdatum | S1: Quelle (PROV)
B2: Erforderlich für Merkmalkatalog
B3: Erforderlich für Data Dictionary
B4: Sprachen | D4: multilingual | E4: multilingual | G4: DE | H4: FR | I4: IT | J4: EN | K4: EN | L4: DE | M4: FR | N4: IT | O4: multilingual | Q4: multilingual | R4: multilingual | S4: multilingual
B5: Referenziert / System generiert | D5: system-generated | E5: system-generated | Q5: referenced | R5: referenced | S5: referenced
B6: Dropdown Liste | Q6: Status
B7: Validierung | D7: not validated. Info: If available system-generated URI / user defined backend reference | E7: system-generated from Designation (EN) | G7: user defined | H7: user defined | I7: user defined | J7: user defined | K7: must use JSON-style list syntax, e.g. ["A", "B", "C"] or ["A", 1.5, "C"] for alphanumeric/numeric values | L7: must use JSON-style list syntax, e.g. ["A", "B", "C"] or ["A", 1.5, "C"] for alphanumeric/numeric values | M7: must use JSON-style list syntax, e.g. ["A", "B", "C"] or ["A", 1.5, "C"] for alphanumeric/numeric values | N7: must use JSON-style list syntax, e.g. ["A", "B", "C"] or ["A", 1.5, "C"] for alphanumeric/numeric values | O7: user defined | Q7: must match Dropdownregeln.Status | R7: date format YYYY-MM-DD | S7: user defined
F8: BDCH_V_31030000 | K8: "GFA","PARKING","USERDEFINED" | L8: "GFA","PARKING","USERDEFINED" | M8: "GFA","PARKING","USERDEFINED"
F9: BDCH_V_31030001 | K9: "SITE_AREA","LANDSCAPE_AREA","ROOM,EXTERNAL_ROOM","RENTABLE_AREA" | L9: "SITE_AREA","LANDSCAPE_AREA","ROOM,EXTERNAL_ROOM","RENTABLE_AREA" | M9: "SITE_AREA","LANDSCAPE_AREA","ROOM,EXTERNAL_ROOM","RENTABLE_AREA"
F10: BDCH_V_31030002 | G10: =[4]Merkmale_Merkmalsgruppen!F8 -> Vordefinierter Typ
F11: BDCH_V_31030003 | G11: =[4]Merkmale_Merkmalsgruppen!F9 -> Objekttyp
F12: BDCH_V_31030004 | G12: =[4]Merkmale_Merkmalsgruppen!F10 -> ID | K12: 1.2,1.2.1,1.2.2,2,2.1.1.1,2.1.1.2,2.1.2,2.1.3,3,3.1.1,3.1.2,3.1.3,"AIRSPACE","ROOF" | L12: 1.2,1.2.1,1.2.2,2,2.1.1.1,2.1.1.2,2.1.2,2.1.3,3,3.1.1,3.1.2,3.1.3,"AIRSPACE","ROOF" | M12: 1.2,1.2.1,1.2.2,2,2.1.1.1,2.1.1.2,2.1.2,2.1.3,3,3.1.1,3.1.2,3.1.3,"AIRSPACE","ROOF"
F13: BDCH_V_31030005 | G13: =[4]Merkmale_Merkmalsgruppen!F11 -> Raumbezeichnung | L13: "GSF","UF","BUF","UUF","GF","HNF","NNF","VF","FF","AGF","ANF","AVF","AFF","GV" | M13: "ST","SA","SAA","SAN","SP","SUP","SUS","SD","SI","SEP","SEU","SED","SEI","VB"
F14: BDCH_V_31030006 | G14: =[4]Merkmale_Merkmalsgruppen!F12 -> Flächenart SIA 416 | K14: 1,2,3,4,5,6,7,8,9,10 | L14: 1,2,3,4,5,6,7,8,9,10 | M14: 1,2,3,4,5,6,7,8,9,10
F15: BDCH_V_31030007 | G15: =[4]Merkmale_Merkmalsgruppen!F13 -> Flächenart SIA 416 | L15: "HNF1","HNF2","HNF3","HNF4","HNF5","HNF6","NNF7","FF8","VF9","BUF10" | M15: "SUP1","SUP2","SUP3","SUP4","SUP5","SUP6","SUS7","SI8","SD9","SAA10"
F16: BDCH_V_31030008 | G16: =[4]Merkmale_Merkmalsgruppen!F14 -> Raumbezeichnung SIA 380 | K16: 1.01;1.02;2.01;2.02;3.01;3.02;3.03;3.04;4.01;4.02;4.03;4.04;4.05;5.01;5.02;5.03;6.01;6.02;6.03;6.04;7.01;7.02;7.03;8.01;8.02;8.03;9.01;9.02;9.03;10.01;11.01;11.02;11.03;12.01;12.02;12.03;12.04;12.05;12.06;12.07;12.08;12.09;12.10;12.11;12.12 | L16: 1.01;1.02;2.01;2.02;3.01;3.02;3.03;3.04;4.01;4.02;4.03;4.04;4.05;5.01;5.02;5.03;6.01;6.02;6.03;6.04;7.01;7.02;7.03;8.01;8.02;8.03;9.01;9.02;9.03;10.01;11.01;11.02;11.03;12.01;12.02;12.03;12.04;12.05;12.06;12.07;12.08;12.09;12.10;12.11;12.12 | M16: 1.01;1.02;2.01;2.02;3.01;3.02;3.03;3.04;4.01;4.02;4.03;4.04;4.05;5.01;5.02;5.03;6.01;6.02;6.03;6.04;7.01;7.02;7.03;8.01;8.02;8.03;9.01;9.02;9.03;10.01;11.01;11.02;11.03;12.01;12.02;12.03;12.04;12.05;12.06;12.07;12.08;12.09;12.10;12.11;12.12
F17: BDCH_V_31030009 | G17: =[4]Merkmale_Merkmalsgruppen!F15 -> Raumbezeichnung SIA 380 | L17: "Wohnen Mehrfamilienhaus","Wohnen Einfamilienhaus","Hotelzimmer","Empfang, Lobby","Einzel-, Gruppenbüro","Grossraumbüro","Sitzungszimmer","Schalterhalle, Empfang","Schulzimmer","Lehrerzimmer","Bibliothek","Hörsaal","Schulfachraum","Lebensmittelverkauf","Fachgeschäft","Verkauf Möbel, Bau, Garten","Restaurant","Selbstbedienungsrestaurant","Küche zu Restaurant","Küche zu Selbstbedienungsrestaurant","Vorstellungsraum","Mehrzweckhalle","Ausstellungshalle","Bettenzimmer","Stationszimmer","Behandlungsraum","Produktion (grobe Arbeit)","Produktion (feine Arbeit)","Laborraum","Lagerhalle","Turnhalle","Fitnessraum","Schwimmhalle","Verkehrsfläche","Verkehrsfläche 24 h","Treppenhaus","Nebenraum","Küche, Teeküche","WC, Bad, Dusche","WC","Garderobe, Dusche","Parkhaus","Wasch- und Trockenraum","Kühlraum","Serverraum"
F18: BDCH_V_31030010 | G18: =[4]Merkmale_Merkmalsgruppen!F16 -> Raumnutzung SIA 2024 | K18: 1.1,1.2,1.3,1.4,1.5,1.6,2.1,2.2,2.3,2.4,2.5,2.6,2.7,2.8,3.1,3.2,3.3,3.4,3.5,3.6,3.7,3.8,3.9,4.1,4.2,4.3,4.4,4.5,4.6,5.1,5.2,5.3,5.4,5.5,5.6,5.7,5.8,5.9,6.1,6.2,6.3,6.4,6.5,6.6,6.7,6.8,7.1,7.2,7.3,7.4,7.5,7.6,7.7,8.1,8.2,8.3,8.4,8.5,8.6,8.7,8.8,8.9,9.1,9.2,9.3,9.4,10.1 | L18: 1.1,1.2,1.3,1.4,1.5,1.6,2.1,2.2,2.3,2.4,2.5,2.6,2.7,2.8,3.1,3.2,3.3,3.4,3.5,3.6,3.7,3.8,3.9,4.1,4.2,4.3,4.4,4.5,4.6,5.1,5.2,5.3,5.4,5.5,5.6,5.7,5.8,5.9,6.1,6.2,6.3,6.4,6.5,6.6,6.7,6.8,7.1,7.2,7.3,7.4,7.5,7.6,7.7,8.1,8.2,8.3,8.4,8.5,8.6,8.7,8.8,8.9,9.1,9.2,9.3,9.4,10.1 | M18: 1.1,1.2,1.3,1.4,1.5,1.6,2.1,2.2,2.3,2.4,2.5,2.6,2.7,2.8,3.1,3.2,3.3,3.4,3.5,3.6,3.7,3.8,3.9,4.1,4.2,4.3,4.4,4.5,4.6,5.1,5.2,5.3,5.4,5.5,5.6,5.7,5.8,5.9,6.1,6.2,6.3,6.4,6.5,6.6,6.7,6.8,7.1,7.2,7.3,7.4,7.5,7.6,7.7,8.1,8.2,8.3,8.4,8.5,8.6,8.7,8.8,8.9,9.1,9.2,9.3,9.4,10.1
F19: BDCH_V_31030011 | G19: =[4]Merkmale_Merkmalsgruppen!F17 -> Raumnutzung SIA 2024 | L19: "Wohnräume","Gemeinschaftsräume","Pausenräume","Warteräume","Speiseräume","Hafträume","Büroräume","Grossraumbüros","Besprechungsräume","Konstruktionsräume","Schalterräume","Bedienungsräume","Aufsichtsräume","Bürotechnikräume","Werkhallen","Werkstätten","Technologische Labors","Physikalische, physikaltechnische, elektrotechnische Labors","Chemische, bekteriologische, morphologische Labors","Räume für Tierhaltung","Räume für Pflanzenzucht","Küchen","Sonderarbeitsräume","Lagerräume","Archive, Sammlungsräume","Kühlräume","Annahme- und Ausgaberäume","Verkaufsräume","Ausstellungsräume","Unterrichtsräume mit festem Gestühl","Allgemein Unterrichts- und Übungsräume ohne festes Gestühl","Besondere Unterrichts- und Übungsräume ohne festes Gestühl","Bibliotheksräume","Sporträume","Versammlungsräume","Bühnen-, Studioräume","Schauräume","Sakralräume","Räume mit allgemeiner medizinischen Ausstattung","Räume mit besonderer medizinischen Ausstattung","Räume für operative Eingriffe, Endoskopien und Entbindungen","Räume für Strahlendiagnostik","Räume für Strahlentherapie","Räume für Physiotherapie und Rehabilitation","Bettenräume mit allgemeiner Ausstattung","Bettenräume mit besonderer Ausstattung","Sanitärräume","Garderoben","Abstellräume","Fahrzeugabstellflächen","Fahrgastflächen","Räume für zentrale Technik","Schutzräum","Abwasseraufbereitung u. -beseitigung","Wasserversorgung","Heizung und Brauchwassererwärmung","Gase und Flüssigkeiten","Elektrische Stromversorgung","Fernmeldetechnik","Raumlufttechnische Anlagen","Aufzugs- und Förderanlagen","Sonstige betriebstechnische Anlagen","Flure, Hallen","Treppen","Schächte für Förderanlagen","Fahrzeugverkehrsflächen","aussenliegende Fahrzeugabstellflächen"
F20: BDCH_V_31030012 | G20: =[4]Merkmale_Merkmalsgruppen!F18 -> Flächenart d0165
F21: BDCH_V_31030013 | G21: =[4]Merkmale_Merkmalsgruppen!F19 -> Flächenart d0165
F22: BDCH_V_31030014 | G22: =[4]Merkmale_Merkmalsgruppen!F20 -> Raumnutzung
F23: BDCH_V_31030015 | G23: =[4]Merkmale_Merkmalsgruppen!F21 -> Raumtyp
F24: BDCH_V_31030016 | G24: =[4]Merkmale_Merkmalsgruppen!F22 -> Einheitstyp
F25: BDCH_V_31030017 | G25: =[4]Merkmale_Merkmalsgruppen!F23 -> Einheitsnummer
F26: BDCH_V_31030018 | G26: =[4]Merkmale_Merkmalsgruppen!F24 -> Raumnummer_Betrieb
F27: BDCH_V_31030019 | G27: =[4]Merkmale_Merkmalsgruppen!F25 -> Raumbeschriftung
F28: BDCH_V_31030020 | G28: =[4]Merkmale_Merkmalsgruppen!F26 -> Reinigungsgruppe
F29: BDCH_V_31030021 | G29: =[4]Merkmale_Merkmalsgruppen!F27 -> Flächenlast | K29: "true","false" | L29: "true","false" | M29: "true","false"
F30: BDCH_V_31030022 | G30: =[4]Merkmale_Merkmalsgruppen!F28 -> Punktlast
F31: BDCH_V_31030023 | G31: =[4]Merkmale_Merkmalsgruppen!F29 -> Energiebezugsfläche | K31: "true","false" | L31: "true","false" | M31: "true","false"
F32: BDCH_V_31030024 | G32: =[4]Merkmale_Merkmalsgruppen!F30 -> Fensterfläche
F33: BDCH_V_31030025 | G33: =[4]Merkmale_Merkmalsgruppen!F31 -> Fenster öffenbar | K33: "true","false" | L33: "true","false" | M33: "true","false"
F34: BDCH_V_31030026 | G34: =[4]Merkmale_Merkmalsgruppen!F32 -> Raumnutzer | K34: "true","false" | L34: "true","false" | M34: "true","false"
F35: BDCH_V_31030027 | G35: =[4]Merkmale_Merkmalsgruppen!F33 -> Sonnenschutz | K35: "true","false" | L35: "true","false" | M35: "true","false"
F36: BDCH_V_31030028 | G36: =[4]Merkmale_Merkmalsgruppen!F34 -> Befeuchtet | K36: "true","false" | L36: "true","false" | M36: "true","false"
F37: BDCH_V_31030029 | G37: =[4]Merkmale_Merkmalsgruppen!F35 -> Entfeuchtet | K37: "true","false" | L37: "true","false" | M37: "true","false"
F38: BDCH_V_31030030 | G38: =[4]Merkmale_Merkmalsgruppen!F36 -> Vermietbarkeit
F39: BDCH_V_31030031 | G39: =[4]Merkmale_Merkmalsgruppen!F37 -> Aussenraum
F40: BDCH_V_31030032 | G40: =[4]Merkmale_Merkmalsgruppen!F38 -> Nutzungsart
...

Sheet Dokumente
A1: Filter | B1: Hinweise zur Handhabung | C1: Dokumente | D1: URI | E1: Document-ID | F1: Document-Code | G1: DocumentName (EN) | H1: Bezeichnung (DE) | I1: Désignation (FR) | J1: Designazione (IT) | K1: Sicherheitsstufe | L1: Zugänglichkeit | M1: Revision | N1: DocumentOwner | P1: Governance (Dokumente) | Q1: Status | R1: Versionsdatum | S1: Herkunft (PROV)
B2: Erforderlich für Merkmalkatalog
B3: Erforderlich für Data Dictionary
B4: Sprachen | D4: multilingual | E4: multilingual | F4: multilingual | G4: EN | H4: DE | I4: FR | J4: IT | K4: multilingual | L4: multilingual | M4: multilingual | N4: multilingual | Q4: multilingual | R4: multilingual | S4: multilingual
B5: Referenziert / System generiert | E5: system-generated | G5: referenced | M5: referenced | N5: referenced | Q5: referenced | R5: referenced | S5: referenced
B6: Dropdown Liste | K6: ISG - Informationssicherheitsgesetz | L6: FAIR Prinzipien | Q6: Status
B7: Validierung | D7: not validated. Info: If available system-generated URI / user defined backend reference | E7: system-generated from DocumentName (EN) | F7: user defined | G7: user defined | H7: user defined | I7: user defined | J7: user defined | K7: must match Dropdownregeln.ISG - Informationssicherheitsgesetz | L7: must match Dropdownregeln.FAIR Prinzipien | M7: user defined | N7: user defined | Q7: must match Dropdownregeln.Status | R7: date format YYYY-MM-DD | S7: user defined
D8: https://www.kbob.admin.ch/dam/de/sd-web/2VV0AVojWznW/20240424_KBOB-IPB_Anhang_C_-_Dokumenttypenkatalog_2016_DE.xlsx | F8: BdCH_D_31040000 | H8: Dokumenttypenkatalog | K8: nicht klassifiziert | L8: Zugänglich unentgeltlich | M8: 2016 | N8: KBOB

Sheet Merkmalgruppen
A1: Filter | B1: Hinweise zur Handhabung | C1: Merkmalgruppen | D1: Merkmalsgruppe-ID | E1: Merkmalsgruppe-Code | F1: Designation (EN) | G1: Description (EN) | H1: Bezeichnung (DE) | I1: Désignation (FR) | J1: Designazione (IT) | K1: Governance (Merkmalgruppen) | L1: Status | M1: Versionsdatum | N1: Herkunft (PROV)
B2: Erforderlich für Merkmalkatalog
B3: Erforderlich für Data Dictionary
B4: Sprachen | D4: multilingual | E4: multilingual | F4: EN | G4: EN | H4: DE | I4: FR | J4: IT | L4: multilingual | M4: multilingual | N4: multilingual
B5: Referenziert / System generiert | D5: system-generated | L5: referenced | M5: referenced | N5: referenced
B6: Dropdown Liste | L6: Status
B7: Validierung | D7: system-generated from Designation (EN) | E7: user defined | F7: user defined | G7: user defined | H7: user defined | I7: user defined | J7: user defined | L7: must match Dropdownregeln.Status | M7: date format YYYY-MM-DD | N7: user defined
D8: BdCH_AreaMgmt

Sheet Data_Template
C1: MG | E1: Merkmale | BI1: Dokumente
C2: Merkmalgruppe - Bezeichnung/Designation | E2: Merkmal - Bezeichnung/Designation | F2: {=TRANSPOSE([4]Merkmale_Merkmalsgruppen!G8:G60)} -> PredefinedType | G2: ObjectType | H2: Name | I2: LongName | J2: SIA_416_2003_Code | K2: SIA_416_2003_Label | L2: SIA_380_2015_Code | M2: SIA_380_2015_Label | N2: SIA_2024_2021_Code | O2: SIA_2024_2021_Label | P2: SIA_d0615_2000_Code | Q2: SIA_d0615_2000_Label | R2: ProgramUse | S2: RoomType | T2: UnitType | U2: Unit_ID | V2: RoomNumberFM | W2: RoomSignalLabel | X2: CleaningGroup | Y2: AreaLoad | Z2: PointLoad | AA2: EnergyReferenceArea | AB2: WindowsCleaningArea | AC2: WindowsOpenable | AD2: Occupant | AE2: Shading | AF2: IsHumidified | AG2: IsDehumidified | AH2: IsRentable | AI2: IsExternal | AJ2: OccupancyType | AK2: MinimumHeadroom | AL2: OccupancyNumberPeak | AM2: OccupancyNumber | AN2: FloorCovering | AO2: WallCovering | AP2: CeilingCovering | AQ2: NaturalVentilation | AR2: NaturalVentilationRate | AS2: MechanicalVentilation | AT2: MechanicalVentilationRate | AU2: AirConditioning | AV2: TemperatureSetPoint | AW2: HumiditySetPoint | AX2: FireExit | AY2: GrossFloorArea | AZ2: GrossVolume | BA2: NetFloorArea | BB2: NetVolume | BC2: NetWallArea | BD2: Height | BE2: AboveGround | BF2: CostZone | BI2: Dokumente - Bezeichnung/Designation
A3: Objekte
A4: Objekt - Bezeichnung/Designation
A5: Geschossebene | H5: x | I5: x
A6: Grundstückfläche | F6: "USERDEFINED" | G6: "SITE_AREA" | J6: 1 | K6: "GSF","ST" | AI6: "true" | AY6: x
A7: Umgebungsfläche | F7: "USERDEFINED" | G7: "SURROUNDING_AREA" | I7: x | J7: 1.2,1.2.1,1.2.2 | K7: "UF","BUF","UUF","SA","SAA","SAN" | L7: x | R7: x | S7: x | U7: x | AD7: x | AI7: "true" | AN7: x | AY7: x | BF7: x
A8: Geschossvolumen | F8: "GFA" | J8: 2,3,"AIRSPACE","ROOF" | K8: "GF","GV","LUFTRAUM","DACH","SP","VB","SVIDE","TOIT" | R8: x | AD8: x | AI8: x | AY8: x | AZ8: x | BD8: x | BE8: x | BF8: x
A9: Nettogeschossfläche | F9: "USERDEFINED" | G9: "ROOM" | H9: x | I9: x | J9: 2.1.1.1,2.1.1.2,2.1.2,2.1.3 | K9: "HNF","NNF","VF","FF","SUP","SUS","SD","SI" | L9: x | M9: "HNF1","HNF2","HNF3","HNF4","HNF5","HNF6","NNF7","FF8","VF9","BUF10","SUP1","SUP2","SUP3","SUP4","SUP5","SUP6","SUS7","SI8","SD9","SAA10" | N9: x | O9: "Wohnen Mehrfamilienhaus","Wohnen Einfamilienhaus","Hotelzimmer","Empfang, Lobby","Einzel-, Gruppenbüro","Grossraumbüro","Sitzungszimmer","Schalterhalle","Empfang","Schulzimmer","Lehrerzimmer","Bibliothek","Hörsaal","Schulfachraum","Lebensmittelverkauf","Fachgeschäft","Verkauf Möbel, Bau, Garten","Restaurant","Selbstbedienungsrestaurant","Küche zu Restaurant","Küche zu Selbstbedienungsrestaurant","Vorstellungsraum","Mehrzweckhalle","Ausstellungshalle","Bettenzimmer","Stationszimmer","Behandlungsraum","Produktion (grobe Arbeit)","Produktion (feine Arbeit)","Laborraum","Lagerhalle","Turnhalle","Fitnessraum","Schwimmhalle","Verkehrsfläche","Verkehrsfläche 24 h","Treppenhaus","Nebenraum","Küche, Teeküche","WC, Bad, Dusche","WC","Garderobe, Dusche","Parkhaus","Wasch- und Trockenraum","Kühlraum","Serverraum" | P9: x | Q9: "Wohnräume","Gemeinschaftsräume","Pausenräume","Warteräume","Speiseräume","Hafträume","Büroräume","Grossraumbüros","Besprechungsräume","Konstruktionsräume","Schalterräume","Bedienungsräume","Aufsichtsräume","Bürotechnikräume","Werkhallen","Werkstätten","Technologische Labors","Physikalische, physikaltechnische, elektrotechnische Labors","Chemische, bekteriologische, morphologische Labors","Räume für Tierhaltung","Räume für Pflanzenzucht","Küchen","Sonderarbeitsräume","Lagerräume","Archive, Sammlungsräume","Kühlräume","Annahme- und Ausgaberäume","Verkaufsräume","Ausstellungsräume","Unterrichtsräume mit festem Gestühl","Allgemein Unterrichts- und Übungsräume ohne festes Gestühl","Besondere Unterrichts- und Übungsräume ohne festes Gestühl","Bibliotheksräume","Sporträume","Versammlungsräume","Bühnen-, Studioräume","Schauräume","Sakralräume","Räume mit allgemeiner medizinischen Ausstattung","Räume mit besonderer medizinischen Ausstattung","Räume für operative Eingriffe, Endoskopien und Entbindungen","Räume für Strahlendiagnostik","Räume für Strahlentherapie","Räume für Physiotherapie und Rehabilitation","Bettenräume mit allgemeiner Ausstattung","Bettenräume mit besonderer Ausstattung","Sanitärräume","Garderoben","Abstellräume","Fahrzeugabstellflächen","Fahrgastflächen","Räume für zentrale Technik","Schutzräum","Abwasseraufbereitung u. -beseitigung","Wasserversorgung","Heizung und Brauchwassererwärmung","Gase und Flüssigkeiten","Elektrische Stromversorgung","Fernmeldetechnik","Raumlufttechnische Anlagen","Aufzugs- und Förderanlagen","Sonstige betriebstechnische Anlagen","Flure, Hallen","Treppen","Schächte für Förderanlagen" | R9: x | S9: x | U9: x | V9: x | W9: x | X9: x | Y9: x | Z9: x | AA9: x | AB9: x | AC9: x | AD9: x | AE9: x | AF9: x | AG9: x | AH9: x | AI9: "false" | AJ9: x | AK9: x | AL9: x | AM9: x | AN9: x | AO9: x | AP9: x | AQ9: x | AR9: x | AS9: x | AT9: x | AU9: x | AV9: x | AW9: x | AX9: x | BA9: x | BB9: x | BC9: x | BD9: x | BE9: x | BF9: x
A10: Aussen-Nettogeschossfläche | F10: "USERDEFINED" | G10: "EXTERNAL_ROOM" | H10: x | I10: x | J10: 3.1.1,3.1.2,3.1.3 | K10: "ANF","AVF","AFF","SEU","SED","SEI" | R10: x | S10: x | U10: x | AD10: x | AI10: "true" | AJ10: x | AL10: x | AM10: x | AN10: x | BA10: x | BE10: x | BF10: x
A11: Stellplatz | F11: "PARKING" | H11: x | I11: x | P11: x | Q11: "Fahrzeugverkehrsflächen","aussenliegende Fahrzeugabstellflächen" | R11: x | AD11: x | AI11: x | AJ11: x | BA11: x
A12: Vermietbare Fläche | F12: "USERDEFINED" | G12: "RENTABLE_AREA" | H12: x | I12: x | R12: x | T12: x | U12: x | AD12: x | AH12: x | AL12: x | AM12: x | AY12: x | BA12: x

Sheet Gelöschte Bauteile
B1: D | C1: 05 | D1: . | E1: 01 | F1: . | G1: 004 | H1: . | I1: nnn | L1: Schalldämpfer | N1: 242.2 | O1: - | P1: - | Q1: - | R1: x | U1: x | V1: Rohrzubehör | Y1: Apparat HLKS | Z1: IfcDuctSilencerType | AA1: ROUND/RECTANGULAR | AD1: 200 | AE1: 200 | AF1: 300 | AG1: 300 | AH1: 300 | AI1: 300 | AV1: x | BE1: =IF(COUNTIF(AJ1:BD1,"x")>0,"x","") -> x
B2: D | C2: 05 | D2: . | E2: 01 | F2: . | G2: 004 | H2: . | I2: nnn | L2: Dacheinfassung | N2: 242.2 | O2: - | P2: - | Q2: - | R2: x | U2: x | V2: Rohrzubehör | Y2: Installationszubehör | Z2: IfcCoveringType | AA2: ROOFING | AD2: 200 | AE2: 200 | AF2: 300 | AG2: 300 | AH2: 300 | AI2: 300 | AV2: x | BE2: =IF(COUNTIF(AJ2:BD2,"x")>0,"x","") -> x
B3: D | C3: 05 | D3: . | E3: 01 | F3: . | G3: 004 | H3: . | I3: nnn | L3: Revisionsstück | N3: 242.2 | O3: - | P3: - | Q3: - | R3: x | U3: x | V3: Rohrformteile | Z3: IfcPipeSegmentType | AA3: SPOOL | AD3: 200 | AE3: 200 | AF3: 300 | AG3: 300 | AH3: 300 | AI3: 300 | AV3: x | BE3: =IF(COUNTIF(AJ3:BD3,"x")>0,"x","") -> x
B4: D | C4: 05 | D4: . | E4: 01 | F4: . | G4: 004 | H4: . | I4: nnn | L4: Messstutzen | N4: 242.2 | O4: - | P4: - | Q4: - | R4: x | U4: x | V4: Rohrformteile | Z4: IfcPipeFittingType | AA4: ENTRY | AD4: 200 | AE4: 200 | AF4: 300 | AG4: 300 | AH4: 300 | AI4: 300 | AV4: x | BE4: =IF(COUNTIF(AJ4:BD4,"x")>0,"x","") -> x
B5: D | C5: 05 | D5: . | E5: 01 | F5: . | G5: 004 | H5: . | I5: nnn | L5: Abscheider | N5: 242.2 | O5: - | P5: - | Q5: - | R5: x | U5: x | V5: Rohrzubehör | Y5: Armatur HLKS | Z5: IfcValveType | AA5: DRAWOFFCOCK | AD5: 200 | AE5: 200 | AF5: 300 | AG5: 300 | AH5: 300 | AI5: 300 | AV5: x | BE5: =IF(COUNTIF(AJ5:BD5,"x")>0,"x","") -> x
B6: D | C6: 05 | D6: . | E6: 01 | F6: . | G6: 004 | H6: . | I6: nnn | L6: Isolierstück | N6: 242.2 | O6: - | P6: - | Q6: - | R6: x | U6: x | V6: Rohrformteile | Z6: IfcPipeSegmentType | AA6: SPOOL | AD6: 200 | AE6: 200 | AF6: 300 | AG6: 300 | AH6: 300 | AI6: 300 | AV6: x | BE6: =IF(COUNTIF(AJ6:BD6,"x")>0,"x","") -> x
B7: D | C7: 05 | D7: . | E7: 01 | F7: . | G7: 004 | H7: . | I7: nnn | L7: Kontrolldeckel | N7: 242.2 | O7: - | P7: - | Q7: - | R7: x | U7: x | V7: Rohrzubehör | AV7: x | BE7: =IF(COUNTIF(AJ7:BD7,"x")>0,"x","") -> x
B8: D | C8: 05 | D8: . | E8: 01 | F8: . | G8: 004 | H8: . | I8: nnn | L8: Schlammsammler | N8: 242.2 | O8: - | P8: - | Q8: - | R8: x | U8: x | V8: Rohrzubehör | Y8: Apparat HLKS | Z8: IfcFilterType | AA8: WATERFILTER | AD8: 200 | AE8: 200 | AF8: 300 | AG8: 300 | AH8: 300 | AI8: 300 | AV8: x | BE8: =IF(COUNTIF(AJ8:BD8,"x")>0,"x","") -> x
B9: D | C9: 05 | D9: . | E9: 01 | F9: . | G9: 004 | H9: . | I9: nnn | L9: Storzkupplung | N9: 242.2 | O9: - | P9: - | Q9: - | R9: x | U9: x | V9: Rohrformteile | Z9: IfcPipeFittingType | AA9: CONNECTOR | AD9: 200 | AE9: 200 | AF9: 300 | AG9: 300 | AH9: 300 | AI9: 300 | AV9: x | BE9: =IF(COUNTIF(AJ9:BD9,"x")>0,"x","") -> x
B10: D | C10: 05 | D10: . | E10: 02 | F10: . | G10: 009 | H10: . | I10: nnn | L10: Wärmeübertrager | N10: 242.0 | O10: - | P10: - | Q10: - | R10: x | U10: x | V10: HLS-Bauteile | Y10: Apparat HLKS | Z10: IfcHeatExchanger | AA10: - | AD10: 200 | AE10: 200 | AF10: 300 | AG10: 300 | AH10: 300 | AI10: 300 | AV10: x | BE10: =IF(COUNTIF(AJ10:BD10,"x")>0,"x","") -> x
B11: D | C11: 05 | D11: . | E11: 02 | F11: . | G11: 009 | H11: . | I11: nnn | L11: Wassermangelsicherung | N11: 242.2 | O11: - | P11: - | Q11: - | R11: x | U11: x | V11: HLS-Bauteile | Y11: Schaltung & Steuerung HLKSE | Z11: IfcFlowController | AA11: - | AD11: 200 | AE11: 200 | AF11: 300 | AG11: 300 | AH11: 300 | AI11: 300 | AV11: x | BE11: =IF(COUNTIF(AJ11:BD11,"x")>0,"x","") -> x

Sheet Dropdownregeln
A1: Objekt-Einordnung | B1: DataType | C1: IFC Data Type | D1: Category | E1: Base Type | F1: Beschreibung | G1: Status | H1: ISG - Informationssicherheitsgesetz | I1: FAIR Prinzipien
A2: Systeme / Anlagen | B2: BOOLEAN | C2: nicht definiert | D2: n/a | E2: none | G2: Preview | H2: nicht klassifiziert | I2: Zugänglich kostenpflichtig
A3: Physische Bauteile | B3: CHARACTER | C3: IfcBoolean | D3: Simple Defined Type | E3: STRING | F3: Datum | G3: Active | H3: intern | I3: Zugänglich unentgeltlich
A4: Räumliche Struktur | B4: INTEGER | C4: IfcDate | D4: Simple Defined Type | E4: STRING | F4: Datum und Zeit | G4: Inactive | H4: sensitiv | I4: Nicht zugänglich - kostenpflichtig
A5: Logische Zonen & Gruppen | B5: REAL | C5: IfcDateTime | D5: Simple Defined Type | E5: STRING | F5: Zeitdauer | G5: Deprecated | H5: geheim | I5: Nicht zugänglich - unentgeltlich
A6: Geometrische Referenzen & Raster | B6: STRING | C6: IfcDuration | D6: Simple Defined Type | E6: STRING | F6: Globale eindeutige ID | G6: Retired
A7: Akteure | B7: TIME | C7: IfcGloballyUniqueId | D7: Simple Defined Type | E7: STRING | F7: Eindeutiger Identifikator | G7: Candidate
A8: Ressourcen | B8: DATETIME | C8: IfcIdentifier | D8: Simple Defined Type | E8: STRING | F8: Kurze Bezeichnung | G8: Recorded
A9: Prozesse & Aufgaben | C9: IfcLabel | D9: Simple Defined Type | E9: STRING | F9: Längerer Beschreibungstext | G9: Superseded
C10: IfcText | D10: Simple Defined Type | E10: STRING | F10: Uhrzeit | G10: Incomplete
C11: IfcTime | D11: Simple Defined Type | E11: STRING | F11: URI-Referenz
C12: IfcURIReference | E12: REAL | F12: Flächenwert
C13: IfcInteger | E13: REAL | F13: Energie
C14: IfcReal | E14: REAL | F14: Kraft
C15: IfcAreaMeasure | D15: Measure Type | E15: REAL | F15: Längenwert
C16: IfcLinearVelocityMeasure | D16: Measure Type | E16: REAL | F16: Geschwindigkeit
C17: IfcMassDensityMeasure | D17: Measure Type | E17: REAL | F17: Dichte
C18: IfcMassMeasure | D18: Measure Type | E18: REAL | F18: Massenwert
C19: IfcPlanarForceMeasure | D19: Measure Type | E19: REAL | F19: Kraft pro Längeneinheit in einer Ebene
C20: IfcPowerMeasure | D20: Measure Type | E20: REAL | F20: Leistung
C21: IfcPressureMeasure | D21: Measure Type | E21: REAL | F21: Druck
C22: IfcThermodynamicTemperatureMeasure | D22: Measure Type | E22: REAL | F22: Temperatur
C23: IfcTimeMeasure | D23: Measure Type | E23: REAL | F23: Zeitwert
C24: IfcVolumeMeasure | D24: Measure Type | E24: REAL | F24: Volumenwert
C25: IfcVolumetricFlowRateMeasure | D25: Measure Type | E25: REAL | F25: Volumenstrom
C26: IfcDynamicViscosityMeasure | D26: Derived Measure Type | E26: REAL | F26: Dynamische Viskosität
... C28: IfcThermalTransmittanceMeasure | D28: Derived Measure Type | E28: REAL | F28: Wärmedurchgangskoeffizient
